<?xml version="1.0" encoding="utf-8"?>
<!-- This URDF was automatically created by SolidWorks to URDF Exporter! Originally created by Stephen Brawner (brawner@gmail.com) 
     Commit Version: 1.5.0-0-g9aa0fdb  Build Version: 1.5.7004.21443
     For more information, please see http://wiki.ros.org/sw_urdf_exporter -->
<robot  name="mr100" xmlns:xacro="http://www.ros.org/wiki/xacro" >
	<material name="black">
	   <color rgba="0.0 0.0 0.0 1.0" />
	</material>

        <material name="blue">
           <color rgba="0.203125 0.23828 0.285156 1.0" />
        </material>

        <material name="green">
           <color rgba="0.0 0.8 0.0 1.0" />
        </material>

        <material name="grey">
           <color rgba="0.2 0.2 0.2 1.0" />
        </material>

        <material name="orange">
           <color rgba="1.0 0.423529 0.039215 1.0" />
        </material>

        <material name="brown">
           <color rgba="0.870588 0.811764 0.76470 1.0" />
        </material>

        <material name="red">
           <color rgba="0.8 0.1289 0.1328 1.0" />
        </material>

        <material name="white">
           <color rgba="1.0 1.0 1.0 1.0" />
        </material>

	<gazebo reference="base_link">
	   <material>Gazebo/Grey</material> 
	</gazebo>

        <gazebo reference="left_drive_wheel_Link">
           <material>Gazebo/FlatBlack</material>
        </gazebo>

        <gazebo reference="right_drive_wheel_Link">
           <material>Gazebo/FlatBlack</material>
        </gazebo>

        <gazebo reference="front_camera_Link">
           <material>Gazebo/Indigo</material>
        </gazebo>

        <gazebo reference="lidar_Link">
           <material>Gazebo/Red</material>
        </gazebo>

	<xacro:include filename="$(find robot_model)/urdf/sensors.gazebo" />
<link
    name="base_link">
 <pose>0 0 0.1 0 0 0 </pose>
    <inertial>
      <origin
        xyz="0 0  0.003"
        rpy="0 0 0" />
      <mass
        value="82.69" />
      <inertia
        ixx="2.02" ixy="0" ixz="0" iyy="5.28" iyz="0" izz="6.69" />
    </inertial>
    <visual>
      <origin
        xyz="0 0 0.1"
        rpy="0 0 0" />
      <geometry>
        <mesh
          filename="package://robot_model/meshes/base_link.STL" />
      </geometry>
      <material
        name="grey">
        <color
          rgba="0.75 0.75 0.75 1" />
      </material>
    </visual>
    <collision>
      <origin
        xyz="0 0 0.1"
        rpy="0 0 0" />
      <geometry>
        <mesh
          filename="package://robot_model/meshes/base_link.STL" />
      </geometry>
    </collision>
  </link>
  
  <link name="robot_footprint"></link>

  <joint name="robot_footprint_joint" type="fixed">
    <origin xyz="0 0 0" rpy="0 0 0" />
    <parent link="robot_footprint"/>
    <child link="base_link" />
  </joint>


<!--Left Drive Wheel and Joint -->
  <link
    name="left_drive_wheel_Link">
    <inertial>
      <origin
        xyz="0 0 0"
        rpy="0 0 0" />
      <mass
        value="1.2932" />
      <inertia
        ixx="0.0034991" ixy="0.0" ixz="0.0" iyy="0.0066633" iyz="0.0" izz="0.0034991" />
    </inertial>

    <visual>
      <origin
        xyz="-0.1025 0.0 -0.1025"
        rpy="0 0 0" />
      <geometry>
        <mesh
          filename="package://robot_model/meshes/drive_wheel.STL" />
      </geometry>
      <material
        name="black">
        <color
          rgba="0.79216 0.81961 0.93333 1" />
      </material>
    </visual>

    <collision>
      <origin
        xyz="-0.1025 0 -0.1025"
        rpy="0 0 0" />
      <geometry>
        <mesh
          filename="package://robot_model/meshes/drive_wheel.STL" />
      </geometry>
    </collision>
  </link>

  <joint name="left_drive_wheel" type="continuous">
    <origin
      xyz="0 0.215 0.04"
      rpy="0 0 0" />
    <parent link="base_link" />
    <child  link="left_drive_wheel_Link" />
    <axis xyz="0 1 0" rpy="0 0 0"/>
    <limit effort="10000" velocity="10000"/>
    <joint_properties damping="1.0" friction="1.0"/>
  </joint>

<!--Right Drive Wheel and Joint -->
 <link
    name="right_drive_wheel_Link">
    <inertial>
      <origin
        xyz="0 0 0"
        rpy="0 0 0" />
      <mass
        value="1.2932" />
      <inertia
        ixx="0.0034991" ixy="0.0" ixz="0.0" iyy="0.0066633" iyz="0.0" izz="0.0034991" />
    </inertial>

    <visual>
      <origin
        xyz="-0.1025 0.0 -0.1025"
        rpy="0 0 0" />
      <geometry>
        <mesh
          filename="package://robot_model/meshes/drive_wheel.STL" />
      </geometry>
      <material
        name="black">
        <color
          rgba="0.79216 0.81961 0.93333 1" />
      </material>
    </visual>

    <collision>
      <origin
        xyz="-0.1025 0 -0.1025"
        rpy="0 0 0" />
      <geometry>
        <mesh
          filename="package://robot_model/meshes/drive_wheel.STL" />
      </geometry>
    </collision>
  </link>

  <joint name="right_drive_wheel" type="continuous">
    <origin
      xyz="0 -0.255 0.04"
      rpy="0 0 0" />
    <parent link="base_link" />
    <child  link="right_drive_wheel_Link" />
    <axis xyz="0 1 0" rpy="0 0 0"/>
    <limit effort="10000" velocity="10000"/>
    <joint_properties damping="1.0" friction="1.0"/>
  </joint>

<!--Front camera Link and Joint -->
 <link
    name="front_camera_Link">
    <inertial>
      <origin
        xyz="0 0 0"
        rpy="0 0 0" />
      <mass
        value="1.0" />
      <inertia
        ixx="0.1666" ixy="1e-6" ixz="1e-6" iyy="0.1666" iyz="1e-6" izz="0.1666" />
    </inertial>

    <visual>
      <origin
        xyz="0 0 0"
        rpy="1.57 0 1.57" />
      <geometry>
        <mesh
          filename="package://robot_model/meshes/d415.stl" />
      </geometry>
      <material
        name="green">
        <color
          rgba="0.79216 0.81961 0.93333 1" />
      </material>
    </visual>

    <collision>
      <origin
        xyz="0 0 0"
        rpy="1.57 0 1.57" />
      <geometry>
        <mesh
          filename="package://robot_model/meshes/d415.stl" />
      </geometry>
    </collision>
  </link>
  
  <joint name="front_camera" type="fixed">
    <origin
      xyz="0.444 0 0.1"
      rpy="0 0 0" />
    <parent link="base_link" />
    <child  link="front_camera_Link" />
    <axis xyz="0 1 0" rpy="0 0 0"/>
  </joint>

<!--Hokuyo lidar Link and Joint -->
 <link
    name="lidar_Link">
    <inertial>
      <origin
        xyz="0 0 0"
        rpy="0 0 0" />
      <mass
        value="1.0" />
      <inertia
        ixx="0.1666" ixy="1e-6" ixz="1e-6" iyy="0.1666" iyz="1e-6" izz="0.1666" />
    </inertial>

    <visual>
      <origin
        xyz="0 0 0"
        rpy="0 0 0" />
      <geometry>
        <mesh
          filename="package://robot_model/meshes/hokuyo.dae" />
      </geometry>
      <material
        name="red">
        <color
          rgba="0.79216 0.81961 0.93333 1" />
      </material>
    </visual>

    <collision>
      <origin
        xyz="0 0 0"
        rpy="0 0 0" />
      <geometry>
        <mesh
          filename="package://robot_model/meshes/hokuyo.dae" />
      </geometry>
    </collision>
  </link>

  <joint name="lidar_Link" type="fixed">
    <origin
      xyz="0 0 0.24"
      rpy="0 0 0" />
    <parent link="base_link" />
    <child  link="lidar_Link" />
    <axis xyz="0 1 0" rpy="0 0 0"/>
  </joint>

</robot>
